<?xml version="1.0"?>
<robot name="bipedal_walker">
  <!-- Define links and joints for the bipedal walker -->
  <link name="torso">
    <!-- Add visual, collision, and inertial properties for the torso -->
  </link>
  <link name="left_leg">
    <!-- Add visual, collision, and inertial properties for the left leg -->
  </link>
  <link name="right_leg">
    <!-- Add visual, collision, and inertial properties for the right leg -->
  </link>

  <joint name="torso_left_leg_joint" type="revolute">
    <parent link="torso"/>
    <child link="left_leg"/>
    <origin xyz="0 0 0"/>
    <axis xyz="0 1 0"/>
    <limit lower="-1.57" upper="1.57"/>
  </joint>

  <joint name="torso_right_leg_joint" type="revolute">
    <parent link="torso"/>
    <child link="right_leg"/>
    <origin xyz="0 0 0"/>
    <axis xyz="0 -1 0"/>
    <limit lower="-1.57" upper="1.57"/>
  </joint>
</robot>
